---
title: "Класс Exception и его свойства"
ms.custom: 
ms.date: 03/30/2017
ms.prod: .net
ms.reviewer: 
ms.suite: 
ms.technology: dotnet-standard
ms.tgt_pltfrm: 
ms.topic: article
helpviewer_keywords:
- exceptions, Exception class
- Exception class
ms.assetid: e2e1f8c4-e7b4-467d-9a66-13c90861221d
caps.latest.revision: "9"
author: mairaw
ms.author: mairaw
manager: wpickett
ms.openlocfilehash: 253a9846e484aa4e54c3433b0bbc8623519bbb7e
ms.sourcegitcommit: bbde43da655ae7bea1977f7af7345eb87bd7fd5f
ms.translationtype: HT
ms.contentlocale: ru-RU
ms.lasthandoff: 10/21/2017
---
# <a name="exception-class-and-properties"></a>Класс и свойства исключений

<xref:System.Exception> — это базовый класс, от которого наследуются исключения. Например, иерархия класса <xref:System.InvalidCastException> имеет следующий вид:

```
Object
  Exception
    SystemException
       InvalidCastException
```

Класс <xref:System.Exception> имеет следующие свойства, которые облегчают анализ исключения.

| Имя свойства | Описание |
| ------------- | ----------- |
| <xref:System.Exception.Data> | Свойство <xref:System.Collections.IDictionary>, которое содержит произвольные данные в парах "ключ–значение". |
| <xref:System.Exception.HelpLink> | Может содержать URL-адрес (или URN) файла справки, который предоставляет подробные сведения о причине возникновения исключения. |
| <xref:System.Exception.InnerException> | Это свойство может использоваться для создания и сохранения последовательностей исключений во время обработки исключений. Его можно использовать для создания нового исключения, содержащего ранее перехваченные исключения. Исходное исключение может быть перехвачено вторым исключением в свойстве <xref:System.Exception.InnerException>, что позволяет коду, обрабатывающему второе исключение, проверить дополнительные данные. Например, предположим, что у вас есть метод, который принимает аргумент в неправильном формате.  Код пытается считать аргумент, но создается исключение. Метод перехватывает исключение и выдает <xref:System.FormatException>. Чтобы расширить возможности вызывающего объекта для определения причины исключения, иногда желательно, чтобы метод перехватывал исключение, выданное вспомогательной процедурой, а затем выдавал исключение, содержащее больше сведений о возникшей ошибке. Можно создать новое и более информативное исключение, где ссылка на внутреннее исключение может указывать на исходное исключение. Затем это более информативное исключение может выдаваться вызывающему объекту. Обратите внимание, что с помощью данной функции можно создать последовательность связанных исключений, которая завершается первым выданным исключением. |
| <xref:System.Exception.Message> | Предоставляет сведения о причине возникновения исключения.
| <xref:System.Exception.Source> | Возвращает или задает имя приложения или объекта, вызывавшего ошибку. |
| <xref:System.Exception.StackTrace>| Содержит трассировку стека, которую можно использовать для определения места возникновения ошибки. Эта трассировка стека содержит имя исходного файла и, при наличии отладочной информации, номер программной строки. |

Большинство классов, унаследованных от <xref:System.Exception>, не реализуют дополнительные элементы и не предоставляют дополнительные функции. Они просто наследуются от <xref:System.Exception>. Таким образом, наиболее важные сведения для исключения можно найти в иерархии классов исключений, имени исключения и информации, содержащейся в самом исключении.

Рекомендуется создавать и перехватывать только те объекты, которые являются производными от <xref:System.Exception>, но можно создавать любой объект, который является производным от <xref:System.Object> класса в список исключений. Обратите внимание, что не все языки поддерживают создание и перехват объектов, не являющихся производными от <xref:System.Exception>.
  
## <a name="see-also"></a>См. также  
[Исключения](index.md)
